{"name": "Логин курьером с ошибкой в данных", "status": "passed", "start": 1715105422364, "stop": 1715105422749, "uuid": "2d28b6e2-5325-46e6-bce2-c91c53e335ea", "historyId": "0c50a578c0baf84f9e039019e35c0d6c", "testCaseId": "0c50a578c0baf84f9e039019e35c0d6c", "fullName": "tests.tests.TestLoginCourier#test_login_with_mistake", "labels": [{"name": "parentSuite", "value": "tests"}, {"name": "suite", "value": "tests"}, {"name": "subSuite", "value": "TestLoginCourier"}, {"name": "host", "value": "LAPTOP-SSVUBLG9"}, {"name": "thread", "value": "20168-MainThread"}, {"name": "framework", "value": "pytest"}, {"name": "language", "value": "cpython3"}, {"name": "package", "value": "tests.tests"}]}